Workbook
Name ArbBidrag: Skattesatser!$H$3
Name BeFradragHojSats: Skattesatser!$H$4
Name BeFradragKmMax: Skattesatser!$H$6
Name BeFradragKmMin: Skattesatser!$H$5
Name BeFradragLavSats: Skattesatser!$H$7
Name BFradragMax: Skattesatser!$H$10
Name BFradragProc: Skattesatser!$H$9
Name Bundskat: Skattesatser!$H$11
Name EjVSkatGranse: Skattesatser!$H$14
Name EjVSkatMax: Skattesatser!$H$13
Name EjVSkatMin: Skattesatser!$H$12
Name EPENfradragMax: Skattesatser!$H$16
Name EPENfradragProc: Skattesatser!$H$15
Name EPENSeniorMax: Skattesatser!$H$18
Name EPENSeniorProc: Skattesatser!$H$17
Name FagforeningMax: Skattesatser!$H$19
Name FirmabilGranse: Skattesatser!$H$20
Name FirmabilHoj: Skattesatser!$H$22
Name FirmabilLav: Skattesatser!$H$21
Name Forsigtighed: Skattesatser!$H$23
Name FriTelefon: Skattesatser!$H$24
Name Gift: #REF!
Name GranseForhBFdrag: Skattesatser!$H$8
Name GranseNegKIEnlig: Skattesatser!$H$42
Name GranseNegKIPar: Skattesatser!$H$41
Name Grøn_check_antal_børn_max: Skattesatser!#REF!
Name Grøn_check_antal_børn_max: Skattesatser!#REF!
Name Grøn_check_antal_børn_max: Skattesatser!#REF!
Name Grøn_check_antal_børn_max: Skattesatser!#REF!
Name GronCheck: Skattesatser!$H$25
Name GronSkatBorn: Skattesatser!#REF!
Name GronSkatBorn: Skattesatser!#REF!
Name GronSkatBorn: Skattesatser!#REF!
Name GronSkatBorn: Skattesatser!#REF!
Name GronSkatBornexGranse: Skattesatser!#REF!
Name GronSkatBornexGranse: Skattesatser!#REF!
Name GronSkatBornexGranse: Skattesatser!#REF!
Name GronSkatBornexGranse: Skattesatser!#REF!
Name GronSkatexBorn: Skattesatser!#REF!
Name GronSkatexBorn: Skattesatser!#REF!
Name GronSkatexBorn: Skattesatser!#REF!
Name GronSkatexBorn: Skattesatser!#REF!
Name GronSkatMax: Skattesatser!$H$27
Name GronSkatMin: Skattesatser!$H$26
Name GronSkatMod: Skattesatser!$H$28
Name Intro: #REF!
Name Intro: #REF!
Name Intro: #REF!
Name Intro: #REF!
Name Jfradraggranse: Skattesatser!$H$30
Name JfradragMax: Skattesatser!$H$31
Name Jfradragproc: Skattesatser!$H$29
Name KItilTopskatEnlig: Skattesatser!$H$33
Name KItilTopskatPar: Skattesatser!$H$32
Name Personfradrag: Skattesatser!$H$34
Name RatepensionMax: Skattesatser!$H$36
Name Skatteordning: #REF!
Name Skatteordning: #REF!
Name Skatteordning: #REF!
Name Skatteordning: #REF!

Sheet Skat før
B1: Skatteberegningsprogram - enlig | C1: År 2025
C2: Person | I2: =C2 -> Person
B3: Privat indskud på ratepension (og ophørende livrente) | C3: 65500 | I3: Beregnings-grundlag | J3: Beregnet skat
B4: Privat indskud på livrente | C4: 60300 | F4: Beregning af skat | G4: Procent | H4: Fradrag
B5: Alder | C5: =68-15 -> 53 | F5: Bundskat | G5: =Bundskat -> 0.1201 | H5: =Personfradrag -> 51600 | I5: =IF(C35>=0,C31+C35-H5,C31-H5) -> 705800 | J5: =+IF(I5>0,G5*I5,0) -> 84766.58
B6: Har fri telefon (ja/nej) | C6: nej | F6: Topskat | G6: =Topskat -> 0.15 | H6: =TopSkatGranse -> 611800 | I6: =MAX((C70-$H$6),0) -> 145600 | J6: =G6*I6 -> 21840
B7: Fagforening | C7: 0 | F7: Sundhedsbidrag | G7: =Sundhedsbidrag -> 0 | H7: =Personfradrag -> 51600 | I7: =($C$45+AB29)-(H7+AB43) -> 620484 | J7: =+IF(I7>0,I7*G7,0) -> 0
B8: A-kasse og efterløn | C8: 0 | F8: Kommuneskat | G8: =C13 -> 0.263 | H8: =Personfradrag -> 51600 | I8: =($C$45+AB29)-(H8+AB44) -> 620484 | J8: =+IF(I8>0,$C$13*I8,0) -> 163187.29
B9: Antal km til arbejde (tur/retur) | C9: 0 | F9: Kirkeskat | G9: =C14 -> 0.013 | H9: =Personfradrag -> 51600 | I9: =($C$45+AB29)-(H9+AB45) -> 620484 | J9: =+IF(I9>0,$C$14*I9,0) -> 8066.292
B10: Antal arbejdsdage | C10: 0 | J10: =SUM(J5:J9) -> 277860.16
B11: Medlem af Folkekirken (ja/nej) | C11: ja
B12: Vælg Kommune | C12: Lyngby-Taarbæk | F12: Evt skattetillæg af neg. KI under 50.000 | J12: =IF(C35>=0,0,IF(C35>=GranseNegKIEnlig,TillagNegKI*C35,TillagNegKI*GranseNegKIEnlig)) -> 0
B13: Kommuneskattesats | C13: =VLOOKUP($C$12,Skattesatser!$B$6:$E$103,2)/100 -> 0.263 | F13: Evt. nedslag i topskatten (lønindkomst) | I13: =IF($C$73>SkraatSkatteloftPI,$C$73-SkraatSkatteloftPI,0) -> 0.0124 | J13: =-I13*C75 -> -1805.44
B14: Kirkeskattesats | C14: =IF(C11="ja",VLOOKUP($C$12,Skattesatser!$B$6:$E$103,3)/100,0) -> 0.013 | F14: Evt. nedslag i topskatten (kapitalindkomst) | I14: =IF($C$73>SkraatSkatteloftKI,$C$73-SkraatSkatteloftKI,0) -> 0.1131 | J14: =-I14*C76 -> 0
B15: Grundskyldssats | C15: =VLOOKUP($C$12,Skattesatser!$B$6:$E$103,4)/1000 -> 0.0127 | J15: =SUM(J10:J14) -> 276054.72
B16: Ejendomsværdi (offentlig) | C16: 0
B17: Grundværdi (offentlig) | C17: 0
B18: Evt skatterabat (bolig købt før 1.jan.2024) | C18: 0 | F18: Indkomstskat i alt (incl. AM-bidrag) | J18: =J15+C27 -> 352854.72
F19: Ejendomsværdiskat | J19: =+F63 -> 0
B20: Lønindkomst (efter evt. ATP) | C20: =12*80000 -> 960000 | F20: Grundskyld | J20: =F64 -> 0
B21: arbejdsgiverpensionsordning % (kun eget indskud) | C21: 0 | F21: Skatterabat | J21: =-C18 -> 0
B22: - arbejdsgiverpensionsordning DKK (kun eget indskud) | C22: =C21*C20 -> 0
B23: + anden AM-pligtig indkomst | C23: 0 | F23: Skat i alt | J23: =SUM(J18:J21) -> 352854.72
B24: + fri telefon | C24: =IF(C6="ja",FriTelefon,0) -> 0
B25: = Beregningsgrundlag for AM-bidrag | C25: =C20-C22+C23+C24 -> 960000
F26: Udbetalt efter skat | I26: =C2 -> Person
B27: - AM-bidrag | C27: =ArbBidrag*C25 -> 76800 | I27: Pr. år | J27: Pr. måned
B28: + Ikke AM-pligtig indkomst (SU, dagpenge, pension etc.) | C28: 0 | F28: Lønindkomst | I28: =C20+C23+C28 -> 960000 | J28: =I28/12 -> 80000
B29: - Eget indskud på ratepension (husk også at indtaste i budget) | C29: =IF(C3>RatepensionMax,RatepensionMax,C3) -> 65500 | F29: - arbejdsgiver pensionsordning | I29: =C22 -> 0 | J29: =I29/12 -> 0
B30: - Eget indskud på livrente (husk også at indtaste i budget) | C30: =+C4 -> 60300 | F30: - skat | I30: =J23 -> 352854.72 | J30: =I30/12 -> 29404.56
B31: = Personlig indkomst (PI) | C31: =C25-C27+C28-C29-C30 -> 757400 | F31: Udbetalt efter skat | I31: =I28-I29-I30 -> 607145.28 | J31: =I31/12 -> 50595.44
B33: + Renteindtægter | C33: 0
B34: - Renteudgfter | C34: 0
B35: + Kapitalindkomst (KI) i alt | C35: =+C33-C34 -> 0
B37: Beskæftigelsesfradrag | C37: =MIN(+($C$25+$C$22*3)*BFradragProc,BFradragMax) -> 55600
B38: Jobfradrag | C38: =MAX(0,MIN(+($C$25+$C$22*3-Jfradraggranse)*Jfradragproc,JfradragMax)) -> 2900
B39: Ekstra pensionsfradrag | C39: =IF(C5<=52,MIN(+(C3+C4+C22*3)*EPENfradragProc,EPENfradragMax),MIN(+(C3+C4+C22*3)*EPENSeniorProc,EPENSeniorMax)) -> 26816
B40: Fagforening, A-kasse og efterløn | C40: =IF(C7>FagforeningMax,FagforeningMax,C7)+C8 -> 0
B41: Befordring | C41: =+$H$56 -> 0
B42: Andre ligningsmæssige fradrag | C42: 0
...

Sheet Tom bo (60%)
C2: indbetaling før omk. | D2: =D4/0.8 -> 0 | E2: =D2/12 -> 0 | F2: pr. mdr
B3: helårlig rentetilskrivning i opsparingsperioden | F3: 2025 | G3: helårlig rentetilskrivning
C4: indbetaling efter omk. | D4: 0 | E4: nuv. pensionsformue | F4: 0 | G4: I udbetalingsperioden
C5: inflation | D5: 0 | E5: til forrentning i antal år | F5: 15 | H5: inflation | I5: 0 | M5: 1 | N5: Friværdi i bolig bør også indgå i det samlede overblik
C6: afkast | D6: 0 | E6: =(1+$D$6/2)^2-1 -> 0 | H6: afkast | I6: 0 | K6: friværdi + anden formue | M6: 2 | N6: Omkostninger =Forsikringer, adm & AMB udgør i gns. Ca 20 % af indbetalingerne
C7: pal skat | D7: 0.153 | E7: FV af pensionsformue | F7: =FV($D$6*(1-$D$7),$F$5,0,-$F$4) -> 0 | H7: pal skat | I7: 0.153 | K7: =460000*0.6+6000000/2*60% -> 2076000 | M7: 3 | N7: Anden formue (kapitalpension, værdipapir, frie midler osv)
E8: NV af pensionsformue | F8: =PV($D$5,$F$5,0,-$F$7) -> 0 | G8: tidspunkt | H8: udbetaling | I8: pensionsformue | K8: =K7/20 -> 103800 | L8: netto
B9: primo | C9: årlig indbetaling | D9: Rente | E9: ultimo | F9: nutidsværdi | G9: 0 | I9: =VLOOKUP(F5,B3:F59,5,FALSE)+F8 -> 0 | K9: =K8/0.63 -> 164761.9 | L9: brutto ***
B10: 1 | C10: =D4 -> 0 | D10: =C10/2*(1-$D$7)*$D$6 -> 0 | E10: =C10+D10 -> 0 | F10: =PV($D$5,B10,0,-E10) -> 0 | G10: =G9+1 -> 1 | H10: 0 | I10: =(I9-H10/2)*$I$6*(1-$I$7)+I9-H10 -> 0
B11: =B10+1 -> 2 | C11: =D4*(1+$D$5) -> 0 | D11: =(E10+C11/2)*(1-$D$7)*$D$6 -> 0 | E11: =E10+C11+D11 -> 0 | F11: =PV($D$5,B11,0,-E11) -> 0 | G11: =G10+1 -> 2 | H11: =H10*(1+$I$5) -> 0 | I11: =(I10-H11/2)*$I$6*(1-$I$7)+I10-H11 -> 0 | J11: Målsøgning findes under :DATA-Hvad hvis- analyse
B12: =B11+1 -> 3 | C12: =C11*(1+$D$5) -> 0 | D12: =(E11+C12/2)*(1-$D$7)*$D$6 -> 0 | E12: =E11+C12+D12 -> 0 | F12: =PV($D$5,B12,0,-E12) -> 0 | G12: =G11+1 -> 3 | H12: =H11*(1+$I$5) -> 0 | I12: =(I11-H12/2)*$I$6*(1-$I$7)+I11-H12 -> 0 | O12: Folkepension 2025 | Q12: pr. mdr | R12: pr. år
B13: =B12+1 -> 4 | C13: =C12*(1+$D$5) -> 0 | D13: =(E12+C13/2)*(1-$D$7)*$D$6 -> 0 | E13: =E12+C13+D13 -> 0 | F13: =PV($D$5,B13,0,-E13) -> 0 | G13: =G12+1 -> 4 | H13: =H12*(1+$I$5) -> 0 | I13: =(I12-H13/2)*$I$6*(1-$I$7)+I12-H13 -> 0 | J13: What if analyse kan også laves på indbetalingerne | P13: Grundbeløb | Q13: 7198 | R13: =Q13*12 -> 86376
B14: =B13+1 -> 5 | C14: =C13*(1+$D$5) -> 0 | D14: =(E13+C14/2)*(1-$D$7)*$D$6 -> 0 | E14: =E13+C14+D14 -> 0 | F14: =PV($D$5,B14,0,-E14) -> 0 | G14: =G13+1 -> 5 | H14: =H13*(1+$I$5) -> 0 | I14: =(I13-H14/2)*$I$6*(1-$I$7)+I13-H14 -> 0 | J14: samt alle de gule felter (husk ingen formler) | P14: tillæg enlig | Q14: 8329 | R14: =Q14*12 -> 99948
B15: =B14+1 -> 6 | C15: =C14*(1+$D$5) -> 0 | D15: =(E14+C15/2)*(1-$D$7)*$D$6 -> 0 | E15: =E14+C15+D15 -> 0 | F15: =PV($D$5,B15,0,-E15) -> 0 | G15: =G14+1 -> 6 | H15: =H14*(1+$I$5) -> 0 | I15: =(I14-H15/2)*$I$6*(1-$I$7)+I14-H15 -> 0 | P15: tillæg par | Q15: 4262 | R15: =Q15*12 -> 51144 | S15: pr. stk
B16: =B15+1 -> 7 | C16: =C15*(1+$D$5) -> 0 | D16: =(E15+C16/2)*(1-$D$7)*$D$6 -> 0 | E16: =E15+C16+D16 -> 0 | F16: =PV($D$5,B16,0,-E16) -> 0 | G16: =G15+1 -> 7 | H16: =H15*(1+$I$5) -> 0 | I16: =(I15-H16/2)*$I$6*(1-$I$7)+I15-H16 -> 0
B17: =B16+1 -> 8 | C17: =C16*(1+$D$5) -> 0 | D17: =(E16+C17/2)*(1-$D$7)*$D$6 -> 0 | E17: =E16+C17+D17 -> 0 | F17: =PV($D$5,B17,0,-E17) -> 0 | G17: =G16+1 -> 8 | H17: =H16*(1+$I$5) -> 0 | I17: =(I16-H17/2)*$I$6*(1-$I$7)+I16-H17 -> 0 | P17: ATP | Q17: pr. mdr | R17: pr. år
B18: =B17+1 -> 9 | C18: =C17*(1+$D$5) -> 0 | D18: =(E17+C18/2)*(1-$D$7)*$D$6 -> 0 | E18: =E17+C18+D18 -> 0 | F18: =PV($D$5,B18,0,-E18) -> 0 | G18: =G17+1 -> 9 | H18: =H17*(1+$I$5) -> 0 | I18: =(I17-H18/2)*$I$6*(1-$I$7)+I17-H18 -> 0 | P18: Max udbetaling | Q18: =R18/12 -> 2343.25 | R18: 28119
B19: =B18+1 -> 10 | C19: =C18*(1+$D$5) -> 0 | D19: =(E18+C19/2)*(1-$D$7)*$D$6 -> 0 | E19: =E18+C19+D19 -> 0 | F19: =PV($D$5,B19,0,-E19) -> 0 | G19: =G18+1 -> 10 | H19: =H18*(1+$I$5) -> 0 | I19: =(I18-H19/2)*$I$6*(1-$I$7)+I18-H19 -> 0
B20: =B19+1 -> 11 | C20: =C19*(1+$D$5) -> 0 | D20: =(E19+C20/2)*(1-$D$7)*$D$6 -> 0 | E20: =E19+C20+D20 -> 0 | F20: =PV($D$5,B20,0,-E20) -> 0 | G20: =G19+1 -> 11 | H20: =H19*(1+$I$5) -> 0 | I20: =(I19-H20/2)*$I$6*(1-$I$7)+I19-H20 -> 0 | P20: Årsløn før skat | R20: =80000*12 -> 960000
B21: =B20+1 -> 12 | C21: =C20*(1+$D$5) -> 0 | D21: =(E20+C21/2)*(1-$D$7)*$D$6 -> 0 | E21: =E20+C21+D21 -> 0 | F21: =PV($D$5,B21,0,-E21) -> 0 | G21: =G20+1 -> 12 | H21: =H20*(1+$I$5) -> 0 | I21: =(I20-H21/2)*$I$6*(1-$I$7)+I20-H21 -> 0 | P21: 75%/80% af løn | Q21: 0.8 | R21: =R20*Q21 -> 768000
B22: =B21+1 -> 13 | C22: =C21*(1+$D$5) -> 0 | D22: =(E21+C22/2)*(1-$D$7)*$D$6 -> 0 | E22: =E21+C22+D22 -> 0 | F22: =PV($D$5,B22,0,-E22) -> 0 | G22: =G21+1 -> 13 | H22: =H21*(1+$I$5) -> 0 | I22: =(I21-H22/2)*$I$6*(1-$I$7)+I21-H22 -> 0 | P22: Folkepension | R22: =R13 -> 86376 | S22: Tilrettet til nye tal
B23: =B22+1 -> 14 | C23: =C22*(1+$D$5) -> 0 | D23: =(E22+C23/2)*(1-$D$7)*$D$6 -> 0 | E23: =E22+C23+D23 -> 0 | F23: =PV($D$5,B23,0,-E23) -> 0 | G23: =G22+1 -> 14 | H23: =H22*(1+$I$5) -> 0 | I23: =(I22-H23/2)*$I$6*(1-$I$7)+I22-H23 -> 0 | P23: Atp | R23: 17900 | S23: Ændret jf. pensionsinfo
B24: =B23+1 -> 15 | C24: =C23*(1+$D$5) -> 0 | D24: =(E23+C24/2)*(1-$D$7)*$D$6 -> 0 | E24: =E23+C24+D24 -> 0 | F24: =PV($D$5,B24,0,-E24) -> 0 | G24: =G23+1 -> 15 | H24: =H23*(1+$I$5) -> 0 | I24: =(I23-H24/2)*$I$6*(1-$I$7)+I23-H24 -> 0 | P24: Forventet udb. Pension | R24: =26500/2+27000/2+383000/2+92000 -> 310250 | S24: =S23 -> Ændret jf. pensionsinfo | U24: NB! Vi forlænger rate til 20 år. Hvis fastholder de 10 år så vil pansionstallet falde efter 10 år til 39% og de første 10 år vil det være 74%
B25: =B24+1 -> 16 | C25: =C24*(1+$D$5) -> 0 | D25: =(E24+C25/2)*(1-$D$7)*$D$6 -> 0 | E25: =E24+C25+D25 -> 0 | F25: =PV($D$5,B25,0,-E25) -> 0 | G25: =G24+1 -> 16 | H25: =H24*(1+$I$5) -> 0 | I25: =(I24-H25/2)*$I$6*(1-$I$7)+I24-H25 -> 0 | P25: Friværdi + anden formue | R25: =K9 -> 164761.9 | S25: ***
B26: =B25+1 -> 17 | C26: =C25*(1+$D$5) -> 0 | D26: =(E25+C26/2)*(1-$D$7)*$D$6 -> 0 | E26: =E25+C26+D26 -> 0 | F26: =PV($D$5,B26,0,-E26) -> 0 | G26: =G25+1 -> 17 | H26: =H25*(1+$I$5) -> 0 | I26: =(I25-H26/2)*$I$6*(1-$I$7)+I25-H26 -> 0 | P26: Mangler hvert år | R26: =R21-R22-R23-R24-R25 -> 188712.1
B27: =B26+1 -> 18 | C27: =C26*(1+$D$5) -> 0 | D27: =(E26+C27/2)*(1-$D$7)*$D$6 -> 0 | E27: =E26+C27+D27 -> 0 | F27: =PV($D$5,B27,0,-E27) -> 0 | G27: =G26+1 -> 18 | H27: =H26*(1+$I$5) -> 0 | I27: =(I26-H27/2)*$I$6*(1-$I$7)+I26-H27 -> 0
B28: =B27+1 -> 19 | C28: =C27*(1+$D$5) -> 0 | D28: =(E27+C28/2)*(1-$D$7)*$D$6 -> 0 | E28: =E27+C28+D28 -> 0 | F28: =PV($D$5,B28,0,-E28) -> 0 | G28: =G27+1 -> 19 | H28: =H27*(1+$I$5) -> 0 | I28: =(I27-H28/2)*$I$6*(1-$I$7)+I27-H28 -> 0 | P28: Udbetalt pr. år | R28: =R22+R23+R24+R25 -> 579287.9
B29: =B28+1 -> 20 | C29: =C28*(1+$D$5) -> 0 | D29: =(E28+C29/2)*(1-$D$7)*$D$6 -> 0 | E29: =E28+C29+D29 -> 0 | F29: =PV($D$5,B29,0,-E29) -> 0 | G29: =G28+1 -> 20 | H29: =H28*(1+$I$5) -> 0 | I29: =(I28-H29/2)*$I$6*(1-$I$7)+I28-H29 -> 0 | P29: Udbetalt i % | R29: =R28/R20 -> 0.6034249
B30: =B29+1 -> 21 | C30: =C29*(1+$D$5) -> 0 | D30: =(E29+C30/2)*(1-$D$7)*$D$6 -> 0 | E30: =E29+C30+D30 -> 0 | F30: =PV($D$5,B30,0,-E30) -> 0 | G30: =G29+1 -> 21 | H30: =H29*(1+$I$5) -> 0 | I30: =(I29-H30/2)*$I$6*(1-$I$7)+I29-H30 -> 0
B31: =B30+1 -> 22 | C31: =C30*(1+$D$5) -> 0 | D31: =(E30+C31/2)*(1-$D$7)*$D$6 -> 0 | E31: =E30+C31+D31 -> 0 | F31: =PV($D$5,B31,0,-E31) -> 0 | G31: =G30+1 -> 22 | H31: =H30*(1+$I$5) -> 0 | I31: =(I30-H31/2)*$I$6*(1-$I$7)+I30-H31 -> 0
B32: =B31+1 -> 23 | C32: =C31*(1+$D$5) -> 0 | D32: =(E31+C32/2)*(1-$D$7)*$D$6 -> 0 | E32: =E31+C32+D32 -> 0 | F32: =PV($D$5,B32,0,-E32) -> 0 | G32: =G31+1 -> 23 | H32: =H31*(1+$I$5) -> 0 | I32: =(I31-H32/2)*$I$6*(1-$I$7)+I31-H32 -> 0
B33: =B32+1 -> 24 | C33: =C32*(1+$D$5) -> 0 | D33: =(E32+C33/2)*(1-$D$7)*$D$6 -> 0 | E33: =E32+C33+D33 -> 0 | F33: =PV($D$5,B33,0,-E33) -> 0 | G33: =G32+1 -> 24 | H33: =H32*(1+$I$5) -> 0 | I33: =(I32-H33/2)*$I$6*(1-$I$7)+I32-H33 -> 0 | K33: Antag at pensionsalderes efter 2030 fortsat er 68 år
B34: =B33+1 -> 25 | C34: =C33*(1+$D$5) -> 0 | D34: =(E33+C34/2)*(1-$D$7)*$D$6 -> 0 | E34: =E33+C34+D34 -> 0 | F34: =PV($D$5,B34,0,-E34) -> 0 | G34: =G33+1 -> 25 | H34: =H33*(1+$I$5) -> 0 | I34: =(I33-H34/2)*$I$6*(1-$I$7)+I33-H34 -> 0 | K34: Dette er en meget forenklet billede af folkepensionsalderen - vi har bestemt at det kun er disse I skal kende​
B35: =B34+1 -> 26 | C35: =C34*(1+$D$5) -> 0 | D35: =(E34+C35/2)*(1-$D$7)*$D$6 -> 0 | E35: =E34+C35+D35 -> 0 | F35: =PV($D$5,B35,0,-E35) -> 0 | G35: =G34+1 -> 26 | H35: =H34*(1+$I$5) -> 0 | I35: =(I34-H35/2)*$I$6*(1-$I$7)+I34-H35 -> 0 | K35: Kilde: https://star.dk/ydelser/pension-og-efterloen/folkepension-og-foertidspension/folkepension/folkepensionsalderen-nu-og-fremover/​
B36: =B35+1 -> 27 | C36: =C35*(1+$D$5) -> 0 | D36: =(E35+C36/2)*(1-$D$7)*$D$6 -> 0 | E36: =E35+C36+D36 -> 0 | F36: =PV($D$5,B36,0,-E36) -> 0 | G36: =G35+1 -> 27 | H36: =H35*(1+$I$5) -> 0 | I36: =(I35-H36/2)*$I$6*(1-$I$7)+I35-H36 -> 0
B37: =B36+1 -> 28 | C37: =C36*(1+$D$5) -> 0 | D37: =(E36+C37/2)*(1-$D$7)*$D$6 -> 0 | E37: =E36+C37+D37 -> 0 | F37: =PV($D$5,B37,0,-E37) -> 0 | G37: =G36+1 -> 28 | H37: =H36*(1+$I$5) -> 0 | I37: =(I36-H37/2)*$I$6*(1-$I$7)+I36-H37 -> 0
B38: =B37+1 -> 29 | C38: =C37*(1+$D$5) -> 0 | D38: =(E37+C38/2)*(1-$D$7)*$D$6 -> 0 | E38: =E37+C38+D38 -> 0 | F38: =PV($D$5,B38,0,-E38) -> 0 | G38: =G37+1 -> 29 | H38: =H37*(1+$I$5) -> 0 | I38: =(I37-H38/2)*$I$6*(1-$I$7)+I37-H38 -> 0
B39: =B38+1 -> 30 | C39: =C38*(1+$D$5) -> 0 | D39: =(E38+C39/2)*(1-$D$7)*$D$6 -> 0 | E39: =E38+C39+D39 -> 0 | F39: =PV($D$5,B39,0,-E39) -> 0 | G39: =G38+1 -> 30 | H39: =H38*(1+$I$5) -> 0 | I39: =(I38-H39/2)*$I$6*(1-$I$7)+I38-H39 -> 0
B40: =B39+1 -> 31 | C40: =C39*(1+$D$5) -> 0 | D40: =(E39+C40/2)*(1-$D$7)*$D$6 -> 0 | E40: =E39+C40+D40 -> 0 | F40: =PV($D$5,B40,0,-E40) -> 0 | G40: =G39+1 -> 31 | H40: =H39*(1+$I$5) -> 0 | I40: =(I39-H40/2)*$I$6*(1-$I$7)+I39-H40 -> 0
B41: =B40+1 -> 32 | C41: =C40*(1+$D$5) -> 0 | D41: =(E40+C41/2)*(1-$D$7)*$D$6 -> 0 | E41: =E40+C41+D41 -> 0 | F41: =PV($D$5,B41,0,-E41) -> 0 | G41: =G40+1 -> 32 | H41: =H40*(1+$I$5) -> 0 | I41: =(I40-H41/2)*$I$6*(1-$I$7)+I40-H41 -> 0
...

Sheet Tom bo mangler (80%)
C2: indbetaling før omk. | D2: =D4/0.8 -> 231503.28 | E2: =D2/12 -> 19291.94 | F2: pr. mdr | K2: =E2*12 -> 231503.28
B3: helårlig rentetilskrivning i opsparingsperioden | F3: 2025 | G3: helårlig rentetilskrivning
C4: indbetaling efter omk. | D4: 185202.62 | E4: nuv. pensionsformue | F4: 0 | G4: I udbetalingsperioden
C5: inflation | D5: 0.015 | E5: til forrentning i antal år | F5: 15 | H5: inflation | I5: 0.015 | M5: 1 | N5: Friværdi i bolig bør også indgå i det samlede overblik
C6: afkast | D6: 0.05 | E6: =(1+$D$6/2)^2-1 -> 0.050625 | H6: afkast | I6: 0.03 | K6: friværdi + anden formue | M6: 2 | N6: Omkostninger =Forsikringer, adm & AMB udgør i gns. Ca 20 % af indbetalingerne
C7: pal skat | D7: 0.153 | E7: FV af pensionsformue | F7: =FV($D$6*(1-$D$7),$F$5,0,-$F$4) -> 0 | H7: pal skat | I7: 0.153 | K7: =460000*0.6+6000000/2*60% -> 2076000 | M7: 3 | N7: Anden formue (kapitalpension, værdipapir, frie midler osv)
E8: NV af pensionsformue | F8: =PV($D$5,$F$5,0,-$F$7) -> 0 | G8: tidspunkt | H8: udbetaling | I8: pensionsformue | K8: =K7/20 -> 103800 | L8: netto
B9: primo | C9: årlig indbetaling | D9: Rente | E9: ultimo | F9: nutidsværdi | G9: 0 | I9: =VLOOKUP(F5,B3:F59,5,FALSE)+F8 -> 3388965.2 | K9: =K8/0.63 -> 164761.9 | L9: brutto ***
B10: 1 | C10: =D4 -> 185202.62 | D10: =C10/2*(1-$D$7)*$D$6 -> 3921.6655 | E10: =C10+D10 -> 189124.29 | F10: =PV($D$5,B10,0,-E10) -> 186329.35 | G10: =G9+1 -> 1 | H10: 188712.1 | I10: =(I9-H10/2)*$I$6*(1-$I$7)+I9-H10 -> 3283969.1
B11: =B10+1 -> 2 | C11: =D4*(1+$D$5) -> 187980.66 | D11: =(E10+C11/2)*(1-$D$7)*$D$6 -> 11989.904 | E11: =E10+C11+D11 -> 389094.85 | F11: =PV($D$5,B11,0,-E11) -> 377679.49 | G11: =G10+1 -> 2 | H11: =H10*(1+$I$5) -> 191542.78 | I11: =(I10-H11/2)*$I$6*(1-$I$7)+I10-H11 -> 3173438.5 | J11: Målsøgning findes under :DATA-Hvad hvis- analyse
B12: =B11+1 -> 3 | C12: =C11*(1+$D$5) -> 190800.37 | D12: =(E11+C12/2)*(1-$D$7)*$D$6 -> 20518.365 | E12: =E11+C12+D12 -> 600413.58 | F12: =PV($D$5,B12,0,-E12) -> 574185.71 | G12: =G11+1 -> 3 | H12: =H11*(1+$I$5) -> 194415.92 | I12: =(I11-H12/2)*$I$6*(1-$I$7)+I11-H12 -> 3057189.6 | O12: Folkepension 2025 | Q12: pr. mdr | R12: pr. år
B13: =B12+1 -> 4 | C13: =C12*(1+$D$5) -> 193662.38 | D13: =(E12+C13/2)*(1-$D$7)*$D$6 -> 29528.316 | E13: =E12+C13+D13 -> 823604.27 | F13: =PV($D$5,B13,0,-E13) -> 775986.96 | G13: =G12+1 -> 4 | H13: =H12*(1+$I$5) -> 197332.16 | I13: =(I12-H13/2)*$I$6*(1-$I$7)+I12-H13 -> 2935033.5 | J13: What if analyse kan også laves på indbetalingerne | P13: Grundbeløb | Q13: 7198 | R13: =Q13*12 -> 86376
B14: =B13+1 -> 5 | C14: =C13*(1+$D$5) -> 196567.31 | D14: =(E13+C14/2)*(1-$D$7)*$D$6 -> 39041.954 | E14: =E13+C14+D14 -> 1059213.5 | F14: =PV($D$5,B14,0,-E14) -> 983225.9 | G14: =G13+1 -> 5 | H14: =H13*(1+$I$5) -> 200292.14 | I14: =(I13-H14/2)*$I$6*(1-$I$7)+I13-H14 -> 2806775.8 | J14: samt alle de gule felter (husk ingen formler) | P14: tillæg enlig | Q14: 8329 | R14: =Q14*12 -> 99948
B15: =B14+1 -> 6 | C15: =C14*(1+$D$5) -> 199515.82 | D15: =(E14+C15/2)*(1-$D$7)*$D$6 -> 49082.441 | E15: =E14+C15+D15 -> 1307811.8 | F15: =PV($D$5,B15,0,-E15) -> 1196049.1 | G15: =G14+1 -> 6 | H15: =H14*(1+$I$5) -> 203296.52 | I15: =(I14-H15/2)*$I$6*(1-$I$7)+I14-H15 -> 2672216.6 | P15: tillæg par | Q15: 4262 | R15: =Q15*12 -> 51144 | S15: pr. stk
B16: =B15+1 -> 7 | C16: =C15*(1+$D$5) -> 202508.56 | D16: =(E15+C16/2)*(1-$D$7)*$D$6 -> 59673.948 | E16: =E15+C16+D16 -> 1569994.3 | F16: =PV($D$5,B16,0,-E16) -> 1414606.9 | G16: =G15+1 -> 7 | H16: =H15*(1+$I$5) -> 206345.97 | I16: =(I15-H16/2)*$I$6*(1-$I$7)+I15-H16 -> 2531150
B17: =B16+1 -> 8 | C17: =C16*(1+$D$5) -> 205546.19 | D17: =(E16+C17/2)*(1-$D$7)*$D$6 -> 70841.699 | E17: =E16+C17+D17 -> 1846382.2 | F17: =PV($D$5,B17,0,-E17) -> 1639054 | G17: =G16+1 -> 8 | H17: =H16*(1+$I$5) -> 209441.16 | I17: =(I16-H17/2)*$I$6*(1-$I$7)+I16-H17 -> 2383364.4 | P17: ATP | Q17: pr. mdr | R17: pr. år
B18: =B17+1 -> 9 | C18: =C17*(1+$D$5) -> 208629.38 | D18: =(E17+C18/2)*(1-$D$7)*$D$6 -> 82612.013 | E18: =E17+C18+D18 -> 2137623.6 | F18: =PV($D$5,B18,0,-E18) -> 1869549 | G18: =G17+1 -> 9 | H18: =H17*(1+$I$5) -> 212582.78 | I18: =(I17-H18/2)*$I$6*(1-$I$7)+I17-H18 -> 2228642.1 | P18: Max udbetaling | Q18: =R18/12 -> 2343.25 | R18: 28119
B19: =B18+1 -> 10 | C19: =C18*(1+$D$5) -> 211758.82 | D19: =(E18+C19/2)*(1-$D$7)*$D$6 -> 95012.352 | E19: =E18+C19+D19 -> 2444394.8 | F19: =PV($D$5,B19,0,-E19) -> 2106254.9 | G19: =G18+1 -> 10 | H19: =H18*(1+$I$5) -> 215771.52 | I19: =(I18-H19/2)*$I$6*(1-$I$7)+I18-H19 -> 2066759
B20: =B19+1 -> 11 | C20: =C19*(1+$D$5) -> 214935.2 | D20: =(E19+C20/2)*(1-$D$7)*$D$6 -> 108071.37 | E20: =E19+C20+D20 -> 2767401.3 | F20: =PV($D$5,B20,0,-E20) -> 2349339 | G20: =G19+1 -> 11 | H20: =H19*(1+$I$5) -> 219008.09 | I20: =(I19-H20/2)*$I$6*(1-$I$7)+I19-H20 -> 1897484.8 | P20: Årsløn før skat | R20: =80000*12 -> 960000
B21: =B20+1 -> 12 | C21: =C20*(1+$D$5) -> 218159.23 | D21: =(E20+C21/2)*(1-$D$7)*$D$6 -> 121818.97 | E21: =E20+C21+D21 -> 3107379.5 | F21: =PV($D$5,B21,0,-E21) -> 2598973.1 | G21: =G20+1 -> 12 | H21: =H20*(1+$I$5) -> 222293.21 | I21: =(I20-H21/2)*$I$6*(1-$I$7)+I20-H21 -> 1720582.4 | P21: 75%/80% af løn | Q21: 0.8 | R21: =R20*Q21 -> 768000
B22: =B21+1 -> 13 | C22: =C21*(1+$D$5) -> 221431.62 | D22: =(E21+C22/2)*(1-$D$7)*$D$6 -> 136286.34 | E22: =E21+C22+D22 -> 3465097.5 | F22: =PV($D$5,B22,0,-E22) -> 2855333.9 | G22: =G21+1 -> 13 | H22: =H21*(1+$I$5) -> 225627.61 | I22: =(I21-H22/2)*$I$6*(1-$I$7)+I21-H22 -> 1535808.2 | P22: Folkepension | R22: =R13 -> 86376 | S22: juster så det passer
B23: =B22+1 -> 14 | C23: =C22*(1+$D$5) -> 224753.09 | D23: =(E22+C23/2)*(1-$D$7)*$D$6 -> 151506.03 | E23: =E22+C23+D23 -> 3841356.6 | F23: =PV($D$5,B23,0,-E23) -> 3118602.6 | G23: =G22+1 -> 14 | H23: =H22*(1+$I$5) -> 229012.02 | I23: =(I22-H23/2)*$I$6*(1-$I$7)+I22-H23 -> 1342911.4 | P23: Atp | R23: 17900 | S23: =S22 -> juster så det passer
B24: =B23+1 -> 15 | C24: =C23*(1+$D$5) -> 228124.39 | D24: =(E23+C24/2)*(1-$D$7)*$D$6 -> 167511.99 | E24: =E23+C24+D24 -> 4236993 | F24: =PV($D$5,B24,0,-E24) -> 3388965.2 | G24: =G23+1 -> 15 | H24: =H23*(1+$I$5) -> 232447.2 | I24: =(I23-H24/2)*$I$6*(1-$I$7)+I23-H24 -> 1141634.4 | P24: Forventet udb. Pension | R24: =26500/2+27000/2+383000/2+92000+H10 -> 498962.1 | S24: evt. pensionsinfo
B25: =B24+1 -> 16 | C25: =C24*(1+$D$5) -> 231546.25 | D25: =(E24+C25/2)*(1-$D$7)*$D$6 -> 184339.64 | E25: =E24+C25+D25 -> 4652878.9 | F25: =PV($D$5,B25,0,-E25) -> 3666613 | G25: =G24+1 -> 16 | H25: =H24*(1+$I$5) -> 235933.91 | I25: =(I24-H25/2)*$I$6*(1-$I$7)+I24-H25 -> 931711.85 | P25: Friværdi + anden formue | R25: =K9 -> 164761.9 | S25: ***
B26: =B25+1 -> 17 | C26: =C25*(1+$D$5) -> 235019.45 | D26: =(E25+C26/2)*(1-$D$7)*$D$6 -> 202025.96 | E26: =E25+C26+D26 -> 5089924.3 | F26: =PV($D$5,B26,0,-E26) -> 3951742.2 | G26: =G25+1 -> 17 | H26: =H25*(1+$I$5) -> 239472.92 | I26: =(I25-H26/2)*$I$6*(1-$I$7)+I25-H26 -> 712871.23 | P26: Mangler hvert år | R26: =R21-R22-R23-R24-R25 -> 0
B27: =B26+1 -> 18 | C27: =C26*(1+$D$5) -> 238544.74 | D27: =(E26+C27/2)*(1-$D$7)*$D$6 -> 220609.48 | E27: =E26+C27+D27 -> 5549078.5 | F27: =PV($D$5,B27,0,-E27) -> 4244554.4 | G27: =G26+1 -> 18 | H27: =H26*(1+$I$5) -> 243065.02 | I27: =(I26-H27/2)*$I$6*(1-$I$7)+I26-H27 -> 484832.13
B28: =B27+1 -> 19 | C28: =C27*(1+$D$5) -> 242122.91 | D28: =(E27+C28/2)*(1-$D$7)*$D$6 -> 240130.43 | E28: =E27+C28+D28 -> 6031331.8 | F28: =PV($D$5,B28,0,-E28) -> 4545256.8 | G28: =G27+1 -> 19 | H28: =H27*(1+$I$5) -> 246710.99 | I28: =(I27-H28/2)*$I$6*(1-$I$7)+I27-H28 -> 247306.26 | P28: Udbetalt pr. år | R28: =R22+R23+R24+R25 -> 768000
B29: =B28+1 -> 20 | C29: =C28*(1+$D$5) -> 245754.76 | D29: =(E28+C29/2)*(1-$D$7)*$D$6 -> 260630.76 | E29: =E28+C29+D29 -> 6537717.3 | F29: =PV($D$5,B29,0,-E29) -> 4854061.7 | G29: =G28+1 -> 20 | H29: =H28*(1+$I$5) -> 250411.66 | I29: =(I28-H29/2)*$I$6*(1-$I$7)+I28-H29 -> -2.8250703 | P29: Udbetalt i % | R29: =R28/R20 -> 0.8
B30: =B29+1 -> 21 | C30: =C29*(1+$D$5) -> 249441.08 | D30: =(E29+C30/2)*(1-$D$7)*$D$6 -> 282154.24 | E30: =E29+C30+D30 -> 7069312.7 | F30: =PV($D$5,B30,0,-E30) -> 5171187.7 | G30: =G29+1 -> 21 | H30: =H29*(1+$I$5) -> 254167.83 | I30: =(I29-H30/2)*$I$6*(1-$I$7)+I29-H30 -> -257399.93
B31: =B30+1 -> 22 | C31: =C30*(1+$D$5) -> 253182.69 | D31: =(E30+C31/2)*(1-$D$7)*$D$6 -> 304746.54 | E31: =E30+C31+D31 -> 7627241.9 | F31: =PV($D$5,B31,0,-E31) -> 5496858.9 | G31: =G30+1 -> 22 | H31: =H30*(1+$I$5) -> 257980.35 | I31: =(I30-H31/2)*$I$6*(1-$I$7)+I30-H31 -> -525198.45 | P31: mangler at betale pr. mdr. | R31: =E2 -> 19291.94 | S31: før skat
B32: =B31+1 -> 23 | C32: =C31*(1+$D$5) -> 256980.43 | D32: =(E31+C32/2)*(1-$D$7)*$D$6 -> 328455.26 | E32: =E31+C32+D32 -> 8212677.6 | F32: =PV($D$5,B32,0,-E32) -> 5831305.6 | G32: =G31+1 -> 23 | H32: =H31*(1+$I$5) -> 261850.05 | I32: =(I31-H32/2)*$I$6*(1-$I$7)+I31-H32 -> -803720.6 | P32: mangler at betale pr. mdr. | R32: =R31*0.48 -> 9260.131 | S32: efter skat | T32: gæt topskat
B33: =B32+1 -> 24 | C33: =C32*(1+$D$5) -> 260835.14 | D33: =(E32+C33/2)*(1-$D$7)*$D$6 -> 353330.08 | E33: =E32+C33+D33 -> 8826842.8 | F33: =PV($D$5,B33,0,-E33) -> 6174764.2 | G33: =G32+1 -> 24 | H33: =H32*(1+$I$5) -> 265777.8 | I33: =(I32-H33/2)*$I$6*(1-$I$7)+I32-H33 -> -1093297.7 | P33: mangler at betale pr. mdr. | R33: =#REF! -> #REF! | S33: efter skat | T33: Jf. skatteberegner. Hans indkomst er ikke stor nok til at han kan trække hele imerindskuddet fra i topskatten
B34: =B33+1 -> 25 | C34: =C33*(1+$D$5) -> 264747.67 | D34: =(E33+C34/2)*(1-$D$7)*$D$6 -> 379422.82 | E34: =E33+C34+D34 -> 9471013.3 | F34: =PV($D$5,B34,0,-E34) -> 6527477.6 | G34: =G33+1 -> 25 | H34: =H33*(1+$I$5) -> 269764.47 | I34: =(I33-H34/2)*$I$6*(1-$I$7)+I33-H34 -> -1394270.2
B35: =B34+1 -> 26 | C35: =C34*(1+$D$5) -> 268718.88 | D35: =(E34+C35/2)*(1-$D$7)*$D$6 -> 406787.54 | E35: =E34+C35+D35 -> 10146520 | F35: =PV($D$5,B35,0,-E35) -> 6889695.1 | G35: =G34+1 -> 26 | H35: =H34*(1+$I$5) -> 273810.94 | I35: =(I34-H35/2)*$I$6*(1-$I$7)+I34-H35 -> -1706988.3 | K35: Antag at pensionsalderes efter 2030 fortsat er 68 år
B36: =B35+1 -> 27 | C36: =C35*(1+$D$5) -> 272749.66 | D36: =(E35+C36/2)*(1-$D$7)*$D$6 -> 435480.58 | E36: =E35+C36+D36 -> 10854750 | F36: =PV($D$5,B36,0,-E36) -> 7261672.9 | G36: =G35+1 -> 27 | H36: =H35*(1+$I$5) -> 277918.1 | I36: =(I35-H36/2)*$I$6*(1-$I$7)+I35-H36 -> -2031811.9 | K36: Dette er en meget forenklet billede af folkepensionsalderen - vi har bestemt at det kun er disse I skal kende​
B37: =B36+1 -> 28 | C37: =C36*(1+$D$5) -> 276840.91 | D37: =(E36+C37/2)*(1-$D$7)*$D$6 -> 465560.77 | E37: =E36+C37+D37 -> 11597152 | F37: =PV($D$5,B37,0,-E37) -> 7643673.9 | G37: =G36+1 -> 28 | H37: =H36*(1+$I$5) -> 282086.87 | I37: =(I36-H37/2)*$I$6*(1-$I$7)+I36-H37 -> -2369111 | K37: Kilde: https://star.dk/ydelser/pension-og-efterloen/folkepension-og-foertidspension/folkepension/folkepensionsalderen-nu-og-fremover/​
B38: =B37+1 -> 29 | C38: =C37*(1+$D$5) -> 280993.52 | D38: =(E37+C38/2)*(1-$D$7)*$D$6 -> 497089.41 | E38: =E37+C38+D38 -> 12375235 | F38: =PV($D$5,B38,0,-E38) -> 8035968.3 | G38: =G37+1 -> 29 | H38: =H37*(1+$I$5) -> 286318.18 | I38: =(I37-H38/2)*$I$6*(1-$I$7)+I37-H38 -> -2719266
B39: =B38+1 -> 30 | C39: =C38*(1+$D$5) -> 285208.43 | D39: =(E38+C39/2)*(1-$D$7)*$D$6 -> 530130.47 | E39: =E38+C39+D39 -> 13190573 | F39: =PV($D$5,B39,0,-E39) -> 8438833.3 | G39: =G38+1 -> 30 | H39: =H38*(1+$I$5) -> 290612.95 | I39: =(I38-H39/2)*$I$6*(1-$I$7)+I38-H39 -> -3082667.7
B40: =B39+1 -> 31 | C40: =C39*(1+$D$5) -> 289486.55 | D40: =(E39+C40/2)*(1-$D$7)*$D$6 -> 564750.66 | E40: =E39+C40+D40 -> 14044811 | F40: =PV($D$5,B40,0,-E40) -> 8852553.9 | G40: =G39+1 -> 31 | H40: =H39*(1+$I$5) -> 294972.14 | I40: =(I39-H40/2)*$I$6*(1-$I$7)+I39-H40 -> -3459718.1
B41: =B40+1 -> 32 | C41: =C40*(1+$D$5) -> 293828.85 | D41: =(E40+C41/2)*(1-$D$7)*$D$6 -> 601019.56 | E41: =E40+C41+D41 -> 14939659 | F41: =PV($D$5,B41,0,-E41) -> 9277422.5 | G41: =G40+1 -> 32 | H41: =H40*(1+$I$5) -> 299396.73 | I41: =(I40-H41/2)*$I$6*(1-$I$7)+I40-H41 -> -3850830.1
...

Sheet Skat bo (80%)
B1: Skatteberegningsprogram - enlig | C1: År 2024
C2: Person | I2: =C2 -> Person
B3: Privat indskud på ratepension (og ophørende livrente) | C3: 65500 | I3: Beregnings-grundlag | J3: Beregnet skat
B4: Privat indskud på livrente | C4: =58100+'Tom bo mangler (80%)'!D2 -> 289603.28 | F4: Beregning af skat | G4: Procent | H4: Fradrag
B5: Alder | C5: 53 | F5: Bundskat | G5: =Bundskat -> 0.1201 | H5: =Personfradrag -> 51600 | I5: =IF(C35>=0,C31+C35-H5,C31-H5) -> 476496.72 | J5: =+IF(I5>0,G5*I5,0) -> 57227.257
B6: Har fri telefon (ja/nej) | C6: nej | F6: Topskat | G6: =Topskat -> 0.15 | H6: =TopSkatGranse -> 611800 | I6: =MAX((C70-$H$6),0) -> 0 | J6: =G6*I6 -> 0
B7: Fagforening | C7: 0 | F7: Sundhedsbidrag | G7: =Sundhedsbidrag -> 0 | H7: =Personfradrag -> 51600 | I7: =($C$45+AB29)-(H7+AB43) -> 391180.72 | J7: =+IF(I7>0,I7*G7,0) -> 0
B8: A-kasse og efterløn | C8: 0 | F8: Kommuneskat | G8: =C13 -> 0.2438 | H8: =Personfradrag -> 51600 | I8: =($C$45+AB29)-(H8+AB44) -> 391180.72 | J8: =+IF(I8>0,$C$13*I8,0) -> 95369.861
B9: Antal km til arbejde (tur/retur) | C9: 0 | F9: Kirkeskat | G9: =C14 -> 0.006 | H9: =Personfradrag -> 51600 | I9: =($C$45+AB29)-(H9+AB45) -> 391180.72 | J9: =+IF(I9>0,$C$14*I9,0) -> 2347.0843
B10: Antal arbejdsdage | C10: 0 | J10: =SUM(J5:J9) -> 154944.2
B11: Medlem af Folkekirken (ja/nej) | C11: ja
B12: Vælg Kommune | C12: Lyngby-Taarbæk | F12: Evt skattetillæg af neg. KI under 50.000 | J12: =IF(C35>=0,0,IF(C35>=GranseNegKIEnlig,TillagNegKI*C35,TillagNegKI*GranseNegKIEnlig)) -> 0
B13: Kommuneskattesats | C13: =VLOOKUP($C$12,Skattesatser!$B$6:$E$103,2)/100 -> 0.2438 | F13: Evt. nedslag i topskatten (lønindkomst) | I13: =IF($C$73>SkraatSkatteloftPI,$C$73-SkraatSkatteloftPI,0) -> 0 | J13: =-I13*C75 -> 0
B14: Kirkeskattesats | C14: =IF(C11="ja",VLOOKUP($C$12,Skattesatser!$B$6:$E$103,3)/100,0) -> 0.006 | F14: Evt. nedslag i topskatten (kapitalindkomst) | I14: =IF($C$73>SkraatSkatteloftKI,$C$73-SkraatSkatteloftKI,0) -> 0.0939 | J14: =-I14*C76 -> 0
B15: Grundskyldssats | C15: =VLOOKUP($C$12,Skattesatser!$B$6:$E$103,4)/1000 -> 0.0067 | J15: =SUM(J10:J14) -> 154944.2
B16: Ejendomsværdi (offentlig) | C16: 0
B17: Grundværdi (offentlig) | C17: 0
B18: Evt skatterabat (bolig købt før 1.jan.2024) | C18: 0 | F18: Indkomstskat i alt (incl. AM-bidrag) | J18: =J15+C27 -> 231744.2
F19: Ejendomsværdiskat | J19: =+F63 -> 0
B20: Lønindkomst (efter evt. ATP) | C20: =12*80000 -> 960000 | F20: Grundskyld | J20: =F64 -> 0
B21: arbejdsgiverpensionsordning % (kun eget indskud) | C21: 0 | F21: Skatterabat | J21: =-C18 -> 0
B22: - arbejdsgiverpensionsordning DKK (kun eget indskud) | C22: =C21*C20 -> 0
B23: + anden AM-pligtig indkomst | C23: 0 | F23: Skat i alt | J23: =SUM(J18:J21) -> 231744.2
B24: + fri telefon | C24: =IF(C6="ja",FriTelefon,0) -> 0
B25: = Beregningsgrundlag for AM-bidrag | C25: =C20-C22+C23+C24 -> 960000
F26: Udbetalt efter skat | I26: =C2 -> Person
B27: - AM-bidrag | C27: =ArbBidrag*C25 -> 76800 | I27: Pr. år | J27: Pr. måned
B28: + Ikke AM-pligtig indkomst (SU, dagpenge, pension etc.) | C28: 0 | F28: Lønindkomst | I28: =C20+C23+C28 -> 960000 | J28: =I28/12 -> 80000
B29: - Eget indskud på ratepension (husk også at indtaste i budget) | C29: =IF(C3>RatepensionMax,RatepensionMax,C3) -> 65500 | F29: - arbejdsgiver pensionsordning | I29: =C22 -> 0 | J29: =I29/12 -> 0
B30: - Eget indskud på livrente (husk også at indtaste i budget) | C30: =+C4 -> 289603.28 | F30: - skat | I30: =J23 -> 231744.2 | J30: =I30/12 -> 19312.017
B31: = Personlig indkomst (PI) | C31: =C25-C27+C28-C29-C30 -> 528096.72 | F31: Udbetalt efter skat | I31: =I28-I29-I30 -> 728255.8 | J31: =I31/12 -> 60687.983
B33: + Renteindtægter | C33: 0
B34: - Renteudgfter | C34: 0
B35: + Kapitalindkomst (KI) i alt | C35: =+C33-C34 -> 0 | F35: Samlet skat i dag | I35: ='Skat før'!J23 -> 352854.72
F36: Samlet skat efter egen indbetaling | I36: =J23 -> 231744.2
B37: Beskæftigelsesfradrag | C37: =MIN(+($C$25+$C$22*3)*BFradragProc,BFradragMax) -> 55600 | F37: Sparet skat | I37: =I35-I36 -> 121110.52
B38: Jobfradrag | C38: =MAX(0,MIN(+($C$25+$C$22*3-Jfradraggranse)*Jfradragproc,JfradragMax)) -> 2900 | F38: Pensionsindbetaling | I38: ='Tom bo mangler (80%)'!D2 -> 231503.28
B39: Ekstra pensionsfradrag | C39: =IF(C5<=52,MIN(+(C3+C4+C22*3)*EPENfradragProc,EPENfradragMax),MIN(+(C3+C4+C22*3)*EPENSeniorProc,EPENSeniorMax)) -> 26816 | F39: Netto betalt | I39: =I38-I37 -> 110392.75
B40: Fagforening, A-kasse og efterløn | C40: =IF(C7>FagforeningMax,FagforeningMax,C7)+C8 -> 0
B41: Befordring | C41: =+$H$56 -> 0
...

Sheet Tom salg (70%)
C2: indbetaling før omk. | D2: =D4/0.8 -> 0 | E2: =D2/12 -> 0 | F2: pr. mdr
B3: helårlig rentetilskrivning i opsparingsperioden | F3: 2025 | G3: helårlig rentetilskrivning
C4: indbetaling efter omk. | D4: 0 | E4: nuv. pensionsformue | F4: 0 | G4: I udbetalingsperioden
C5: inflation | D5: 0 | E5: til forrentning i antal år | F5: 15 | H5: inflation | I5: 0 | M5: 1 | N5: Friværdi i bolig bør også indgå i det samlede overblik
C6: afkast | D6: 0 | E6: =(1+$D$6/2)^2-1 -> 0 | H6: afkast | I6: 0 | K6: friværdi + anden formue | M6: 2 | N6: Omkostninger =Forsikringer, adm & AMB udgør i gns. Ca 20 % af indbetalingerne
C7: pal skat | D7: 0.153 | E7: FV af pensionsformue | F7: =FV($D$6*(1-$D$7),$F$5,0,-$F$4) -> 0 | H7: pal skat | I7: 0.153 | K7: =460000*0.6+6000000/2 -> 3276000 | M7: 3 | N7: Anden formue (kapitalpension, værdipapir, frie midler osv)
E8: NV af pensionsformue | F8: =PV($D$5,$F$5,0,-$F$7) -> 0 | G8: tidspunkt | H8: udbetaling | I8: pensionsformue | K8: =K7/20 -> 163800 | L8: netto
B9: primo | C9: årlig indbetaling | D9: Rente | E9: ultimo | F9: nutidsværdi | G9: 0 | I9: =VLOOKUP(F5,B3:F59,5,FALSE)+F8 -> 0 | K9: =K8/0.63 -> 260000 | L9: brutto ***
B10: 1 | C10: =D4 -> 0 | D10: =C10/2*(1-$D$7)*$D$6 -> 0 | E10: =C10+D10 -> 0 | F10: =PV($D$5,B10,0,-E10) -> 0 | G10: =G9+1 -> 1 | H10: 0 | I10: =(I9-H10/2)*$I$6*(1-$I$7)+I9-H10 -> 0
B11: =B10+1 -> 2 | C11: =D4*(1+$D$5) -> 0 | D11: =(E10+C11/2)*(1-$D$7)*$D$6 -> 0 | E11: =E10+C11+D11 -> 0 | F11: =PV($D$5,B11,0,-E11) -> 0 | G11: =G10+1 -> 2 | H11: =H10*(1+$I$5) -> 0 | I11: =(I10-H11/2)*$I$6*(1-$I$7)+I10-H11 -> 0 | J11: Målsøgning findes under :DATA-Hvad hvis- analyse
B12: =B11+1 -> 3 | C12: =C11*(1+$D$5) -> 0 | D12: =(E11+C12/2)*(1-$D$7)*$D$6 -> 0 | E12: =E11+C12+D12 -> 0 | F12: =PV($D$5,B12,0,-E12) -> 0 | G12: =G11+1 -> 3 | H12: =H11*(1+$I$5) -> 0 | I12: =(I11-H12/2)*$I$6*(1-$I$7)+I11-H12 -> 0 | O12: Folkepension 2025 | Q12: pr. mdr | R12: pr. år
B13: =B12+1 -> 4 | C13: =C12*(1+$D$5) -> 0 | D13: =(E12+C13/2)*(1-$D$7)*$D$6 -> 0 | E13: =E12+C13+D13 -> 0 | F13: =PV($D$5,B13,0,-E13) -> 0 | G13: =G12+1 -> 4 | H13: =H12*(1+$I$5) -> 0 | I13: =(I12-H13/2)*$I$6*(1-$I$7)+I12-H13 -> 0 | J13: What if analyse kan også laves på indbetalingerne | P13: Grundbeløb | Q13: 7198 | R13: =Q13*12 -> 86376
B14: =B13+1 -> 5 | C14: =C13*(1+$D$5) -> 0 | D14: =(E13+C14/2)*(1-$D$7)*$D$6 -> 0 | E14: =E13+C14+D14 -> 0 | F14: =PV($D$5,B14,0,-E14) -> 0 | G14: =G13+1 -> 5 | H14: =H13*(1+$I$5) -> 0 | I14: =(I13-H14/2)*$I$6*(1-$I$7)+I13-H14 -> 0 | J14: samt alle de gule felter (husk ingen formler) | P14: tillæg enlig | Q14: 8329 | R14: =Q14*12 -> 99948
B15: =B14+1 -> 6 | C15: =C14*(1+$D$5) -> 0 | D15: =(E14+C15/2)*(1-$D$7)*$D$6 -> 0 | E15: =E14+C15+D15 -> 0 | F15: =PV($D$5,B15,0,-E15) -> 0 | G15: =G14+1 -> 6 | H15: =H14*(1+$I$5) -> 0 | I15: =(I14-H15/2)*$I$6*(1-$I$7)+I14-H15 -> 0 | P15: tillæg par | Q15: 4262 | R15: =Q15*12 -> 51144 | S15: pr. stk
B16: =B15+1 -> 7 | C16: =C15*(1+$D$5) -> 0 | D16: =(E15+C16/2)*(1-$D$7)*$D$6 -> 0 | E16: =E15+C16+D16 -> 0 | F16: =PV($D$5,B16,0,-E16) -> 0 | G16: =G15+1 -> 7 | H16: =H15*(1+$I$5) -> 0 | I16: =(I15-H16/2)*$I$6*(1-$I$7)+I15-H16 -> 0
B17: =B16+1 -> 8 | C17: =C16*(1+$D$5) -> 0 | D17: =(E16+C17/2)*(1-$D$7)*$D$6 -> 0 | E17: =E16+C17+D17 -> 0 | F17: =PV($D$5,B17,0,-E17) -> 0 | G17: =G16+1 -> 8 | H17: =H16*(1+$I$5) -> 0 | I17: =(I16-H17/2)*$I$6*(1-$I$7)+I16-H17 -> 0 | P17: ATP | Q17: pr. mdr | R17: pr. år
B18: =B17+1 -> 9 | C18: =C17*(1+$D$5) -> 0 | D18: =(E17+C18/2)*(1-$D$7)*$D$6 -> 0 | E18: =E17+C18+D18 -> 0 | F18: =PV($D$5,B18,0,-E18) -> 0 | G18: =G17+1 -> 9 | H18: =H17*(1+$I$5) -> 0 | I18: =(I17-H18/2)*$I$6*(1-$I$7)+I17-H18 -> 0 | P18: Max udbetaling | Q18: =R18/12 -> 2343.25 | R18: 28119
B19: =B18+1 -> 10 | C19: =C18*(1+$D$5) -> 0 | D19: =(E18+C19/2)*(1-$D$7)*$D$6 -> 0 | E19: =E18+C19+D19 -> 0 | F19: =PV($D$5,B19,0,-E19) -> 0 | G19: =G18+1 -> 10 | H19: =H18*(1+$I$5) -> 0 | I19: =(I18-H19/2)*$I$6*(1-$I$7)+I18-H19 -> 0
B20: =B19+1 -> 11 | C20: =C19*(1+$D$5) -> 0 | D20: =(E19+C20/2)*(1-$D$7)*$D$6 -> 0 | E20: =E19+C20+D20 -> 0 | F20: =PV($D$5,B20,0,-E20) -> 0 | G20: =G19+1 -> 11 | H20: =H19*(1+$I$5) -> 0 | I20: =(I19-H20/2)*$I$6*(1-$I$7)+I19-H20 -> 0 | P20: Årsløn før skat | R20: =80000*12 -> 960000
B21: =B20+1 -> 12 | C21: =C20*(1+$D$5) -> 0 | D21: =(E20+C21/2)*(1-$D$7)*$D$6 -> 0 | E21: =E20+C21+D21 -> 0 | F21: =PV($D$5,B21,0,-E21) -> 0 | G21: =G20+1 -> 12 | H21: =H20*(1+$I$5) -> 0 | I21: =(I20-H21/2)*$I$6*(1-$I$7)+I20-H21 -> 0 | P21: 75%/80% af løn | Q21: 0.8 | R21: =R20*Q21 -> 768000
B22: =B21+1 -> 13 | C22: =C21*(1+$D$5) -> 0 | D22: =(E21+C22/2)*(1-$D$7)*$D$6 -> 0 | E22: =E21+C22+D22 -> 0 | F22: =PV($D$5,B22,0,-E22) -> 0 | G22: =G21+1 -> 13 | H22: =H21*(1+$I$5) -> 0 | I22: =(I21-H22/2)*$I$6*(1-$I$7)+I21-H22 -> 0 | P22: Folkepension | R22: =R13 -> 86376 | S22: juster så det passer
B23: =B22+1 -> 14 | C23: =C22*(1+$D$5) -> 0 | D23: =(E22+C23/2)*(1-$D$7)*$D$6 -> 0 | E23: =E22+C23+D23 -> 0 | F23: =PV($D$5,B23,0,-E23) -> 0 | G23: =G22+1 -> 14 | H23: =H22*(1+$I$5) -> 0 | I23: =(I22-H23/2)*$I$6*(1-$I$7)+I22-H23 -> 0 | P23: Atp | R23: 17900 | S23: =S22 -> juster så det passer
B24: =B23+1 -> 15 | C24: =C23*(1+$D$5) -> 0 | D24: =(E23+C24/2)*(1-$D$7)*$D$6 -> 0 | E24: =E23+C24+D24 -> 0 | F24: =PV($D$5,B24,0,-E24) -> 0 | G24: =G23+1 -> 15 | H24: =H23*(1+$I$5) -> 0 | I24: =(I23-H24/2)*$I$6*(1-$I$7)+I23-H24 -> 0 | P24: Forventet udb. Pension | R24: =26500/2+27000/2+383000/2+92000 -> 310250 | S24: evt. pensionsinfo | U24: NB! Vi forlænger rate til 20 år. Hvis fastholder de 10 år så vil pansionstallet falde efter 10 år til 39% og de første 10 år vil det være 74%
B25: =B24+1 -> 16 | C25: =C24*(1+$D$5) -> 0 | D25: =(E24+C25/2)*(1-$D$7)*$D$6 -> 0 | E25: =E24+C25+D25 -> 0 | F25: =PV($D$5,B25,0,-E25) -> 0 | G25: =G24+1 -> 16 | H25: =H24*(1+$I$5) -> 0 | I25: =(I24-H25/2)*$I$6*(1-$I$7)+I24-H25 -> 0 | P25: Friværdi + anden formue | R25: =K9 -> 260000 | S25: ***
B26: =B25+1 -> 17 | C26: =C25*(1+$D$5) -> 0 | D26: =(E25+C26/2)*(1-$D$7)*$D$6 -> 0 | E26: =E25+C26+D26 -> 0 | F26: =PV($D$5,B26,0,-E26) -> 0 | G26: =G25+1 -> 17 | H26: =H25*(1+$I$5) -> 0 | I26: =(I25-H26/2)*$I$6*(1-$I$7)+I25-H26 -> 0 | P26: Mangler hvert år | R26: =R21-R22-R23-R24-R25 -> 93474
B27: =B26+1 -> 18 | C27: =C26*(1+$D$5) -> 0 | D27: =(E26+C27/2)*(1-$D$7)*$D$6 -> 0 | E27: =E26+C27+D27 -> 0 | F27: =PV($D$5,B27,0,-E27) -> 0 | G27: =G26+1 -> 18 | H27: =H26*(1+$I$5) -> 0 | I27: =(I26-H27/2)*$I$6*(1-$I$7)+I26-H27 -> 0
B28: =B27+1 -> 19 | C28: =C27*(1+$D$5) -> 0 | D28: =(E27+C28/2)*(1-$D$7)*$D$6 -> 0 | E28: =E27+C28+D28 -> 0 | F28: =PV($D$5,B28,0,-E28) -> 0 | G28: =G27+1 -> 19 | H28: =H27*(1+$I$5) -> 0 | I28: =(I27-H28/2)*$I$6*(1-$I$7)+I27-H28 -> 0 | P28: Udbetalt pr. år | R28: =R22+R23+R24+R25 -> 674526
B29: =B28+1 -> 20 | C29: =C28*(1+$D$5) -> 0 | D29: =(E28+C29/2)*(1-$D$7)*$D$6 -> 0 | E29: =E28+C29+D29 -> 0 | F29: =PV($D$5,B29,0,-E29) -> 0 | G29: =G28+1 -> 20 | H29: =H28*(1+$I$5) -> 0 | I29: =(I28-H29/2)*$I$6*(1-$I$7)+I28-H29 -> 0 | P29: Udbetalt i % | R29: =R28/R20 -> 0.70263125
B30: =B29+1 -> 21 | C30: =C29*(1+$D$5) -> 0 | D30: =(E29+C30/2)*(1-$D$7)*$D$6 -> 0 | E30: =E29+C30+D30 -> 0 | F30: =PV($D$5,B30,0,-E30) -> 0 | G30: =G29+1 -> 21 | H30: =H29*(1+$I$5) -> 0 | I30: =(I29-H30/2)*$I$6*(1-$I$7)+I29-H30 -> 0
B31: =B30+1 -> 22 | C31: =C30*(1+$D$5) -> 0 | D31: =(E30+C31/2)*(1-$D$7)*$D$6 -> 0 | E31: =E30+C31+D31 -> 0 | F31: =PV($D$5,B31,0,-E31) -> 0 | G31: =G30+1 -> 22 | H31: =H30*(1+$I$5) -> 0 | I31: =(I30-H31/2)*$I$6*(1-$I$7)+I30-H31 -> 0
B32: =B31+1 -> 23 | C32: =C31*(1+$D$5) -> 0 | D32: =(E31+C32/2)*(1-$D$7)*$D$6 -> 0 | E32: =E31+C32+D32 -> 0 | F32: =PV($D$5,B32,0,-E32) -> 0 | G32: =G31+1 -> 23 | H32: =H31*(1+$I$5) -> 0 | I32: =(I31-H32/2)*$I$6*(1-$I$7)+I31-H32 -> 0
B33: =B32+1 -> 24 | C33: =C32*(1+$D$5) -> 0 | D33: =(E32+C33/2)*(1-$D$7)*$D$6 -> 0 | E33: =E32+C33+D33 -> 0 | F33: =PV($D$5,B33,0,-E33) -> 0 | G33: =G32+1 -> 24 | H33: =H32*(1+$I$5) -> 0 | I33: =(I32-H33/2)*$I$6*(1-$I$7)+I32-H33 -> 0 | K33: Antag at pensionsalderes efter 2030 fortsat er 68 år
B34: =B33+1 -> 25 | C34: =C33*(1+$D$5) -> 0 | D34: =(E33+C34/2)*(1-$D$7)*$D$6 -> 0 | E34: =E33+C34+D34 -> 0 | F34: =PV($D$5,B34,0,-E34) -> 0 | G34: =G33+1 -> 25 | H34: =H33*(1+$I$5) -> 0 | I34: =(I33-H34/2)*$I$6*(1-$I$7)+I33-H34 -> 0 | K34: Dette er en meget forenklet billede af folkepensionsalderen - vi har bestemt at det kun er disse I skal kende​
B35: =B34+1 -> 26 | C35: =C34*(1+$D$5) -> 0 | D35: =(E34+C35/2)*(1-$D$7)*$D$6 -> 0 | E35: =E34+C35+D35 -> 0 | F35: =PV($D$5,B35,0,-E35) -> 0 | G35: =G34+1 -> 26 | H35: =H34*(1+$I$5) -> 0 | I35: =(I34-H35/2)*$I$6*(1-$I$7)+I34-H35 -> 0 | K35: Kilde: https://star.dk/ydelser/pension-og-efterloen/folkepension-og-foertidspension/folkepension/folkepensionsalderen-nu-og-fremover/​
B36: =B35+1 -> 27 | C36: =C35*(1+$D$5) -> 0 | D36: =(E35+C36/2)*(1-$D$7)*$D$6 -> 0 | E36: =E35+C36+D36 -> 0 | F36: =PV($D$5,B36,0,-E36) -> 0 | G36: =G35+1 -> 27 | H36: =H35*(1+$I$5) -> 0 | I36: =(I35-H36/2)*$I$6*(1-$I$7)+I35-H36 -> 0
B37: =B36+1 -> 28 | C37: =C36*(1+$D$5) -> 0 | D37: =(E36+C37/2)*(1-$D$7)*$D$6 -> 0 | E37: =E36+C37+D37 -> 0 | F37: =PV($D$5,B37,0,-E37) -> 0 | G37: =G36+1 -> 28 | H37: =H36*(1+$I$5) -> 0 | I37: =(I36-H37/2)*$I$6*(1-$I$7)+I36-H37 -> 0
B38: =B37+1 -> 29 | C38: =C37*(1+$D$5) -> 0 | D38: =(E37+C38/2)*(1-$D$7)*$D$6 -> 0 | E38: =E37+C38+D38 -> 0 | F38: =PV($D$5,B38,0,-E38) -> 0 | G38: =G37+1 -> 29 | H38: =H37*(1+$I$5) -> 0 | I38: =(I37-H38/2)*$I$6*(1-$I$7)+I37-H38 -> 0
B39: =B38+1 -> 30 | C39: =C38*(1+$D$5) -> 0 | D39: =(E38+C39/2)*(1-$D$7)*$D$6 -> 0 | E39: =E38+C39+D39 -> 0 | F39: =PV($D$5,B39,0,-E39) -> 0 | G39: =G38+1 -> 30 | H39: =H38*(1+$I$5) -> 0 | I39: =(I38-H39/2)*$I$6*(1-$I$7)+I38-H39 -> 0
B40: =B39+1 -> 31 | C40: =C39*(1+$D$5) -> 0 | D40: =(E39+C40/2)*(1-$D$7)*$D$6 -> 0 | E40: =E39+C40+D40 -> 0 | F40: =PV($D$5,B40,0,-E40) -> 0 | G40: =G39+1 -> 31 | H40: =H39*(1+$I$5) -> 0 | I40: =(I39-H40/2)*$I$6*(1-$I$7)+I39-H40 -> 0
B41: =B40+1 -> 32 | C41: =C40*(1+$D$5) -> 0 | D41: =(E40+C41/2)*(1-$D$7)*$D$6 -> 0 | E41: =E40+C41+D41 -> 0 | F41: =PV($D$5,B41,0,-E41) -> 0 | G41: =G40+1 -> 32 | H41: =H40*(1+$I$5) -> 0 | I41: =(I40-H41/2)*$I$6*(1-$I$7)+I40-H41 -> 0
...

Sheet Tom salg mangler (80%)
C2: indbetaling før omk. | D2: =D4/0.8 -> 114669.64 | E2: =D2/12 -> 9555.8034 | F2: pr. mdr | K2: =E2*12 -> 114669.64
B3: helårlig rentetilskrivning i opsparingsperioden | F3: 2025 | G3: helårlig rentetilskrivning
C4: indbetaling efter omk. | D4: 91735.712 | E4: nuv. pensionsformue | F4: 0 | G4: I udbetalingsperioden
C5: inflation | D5: 0.015 | E5: til forrentning i antal år | F5: 15 | H5: inflation | I5: 0.015 | M5: 1 | N5: Friværdi i bolig bør også indgå i det samlede overblik
C6: afkast | D6: 0.05 | E6: =(1+$D$6/2)^2-1 -> 0.050625 | H6: afkast | I6: 0.03 | K6: friværdi + anden formue | M6: 2 | N6: Omkostninger =Forsikringer, adm & AMB udgør i gns. Ca 20 % af indbetalingerne
C7: pal skat | D7: 0.153 | E7: FV af pensionsformue | F7: =FV($D$6*(1-$D$7),$F$5,0,-$F$4) -> 0 | H7: pal skat | I7: 0.153 | K7: =460000*0.6+6000000/2 -> 3276000 | M7: 3 | N7: Anden formue (kapitalpension, værdipapir, frie midler osv)
E8: NV af pensionsformue | F8: =PV($D$5,$F$5,0,-$F$7) -> 0 | G8: tidspunkt | H8: udbetaling | I8: pensionsformue | K8: =K7/20 -> 163800 | L8: netto
B9: primo | C9: årlig indbetaling | D9: Rente | E9: ultimo | F9: nutidsværdi | G9: 0 | I9: =VLOOKUP(F5,B3:F59,5,FALSE)+F8 -> 1678643.3 | K9: =K8/0.63 -> 260000 | L9: brutto ***
B10: 1 | C10: =D4 -> 91735.712 | D10: =C10/2*(1-$D$7)*$D$6 -> 1942.5037 | E10: =C10+D10 -> 93678.216 | F10: =PV($D$5,B10,0,-E10) -> 92293.809 | G10: =G9+1 -> 1 | H10: 93474 | I10: =(I9-H10/2)*$I$6*(1-$I$7)+I9-H10 -> 1626636
B11: =B10+1 -> 2 | C11: =D4*(1+$D$5) -> 93111.748 | D11: =(E10+C11/2)*(1-$D$7)*$D$6 -> 5938.9137 | E11: =E10+C11+D11 -> 192728.88 | F11: =PV($D$5,B11,0,-E11) -> 187074.55 | G11: =G10+1 -> 2 | H11: =H10*(1+$I$5) -> 94876.11 | I11: =(I10-H11/2)*$I$6*(1-$I$7)+I10-H11 -> 1571887.3 | J11: Målsøgning findes under :DATA-Hvad hvis- analyse
B12: =B11+1 -> 3 | C12: =C11*(1+$D$5) -> 94508.424 | D12: =(E11+C12/2)*(1-$D$7)*$D$6 -> 10163.284 | E12: =E11+C12+D12 -> 297400.59 | F12: =PV($D$5,B12,0,-E12) -> 284409.23 | G12: =G11+1 -> 3 | H12: =H11*(1+$I$5) -> 96299.252 | I12: =(I11-H12/2)*$I$6*(1-$I$7)+I11-H12 -> 1514306.3 | O12: Folkepension 2025 | Q12: pr. mdr | R12: pr. år
B13: =B12+1 -> 4 | C13: =C12*(1+$D$5) -> 95926.051 | D13: =(E12+C13/2)*(1-$D$7)*$D$6 -> 14626.149 | E13: =E12+C13+D13 -> 407952.79 | F13: =PV($D$5,B13,0,-E13) -> 384366.68 | G13: =G12+1 -> 4 | H13: =H12*(1+$I$5) -> 97743.74 | I13: =(I12-H13/2)*$I$6*(1-$I$7)+I12-H13 -> 1453799.2 | J13: What if analyse kan også laves på indbetalingerne | P13: Grundbeløb | Q13: 7198 | R13: =Q13*12 -> 86376
B14: =B13+1 -> 5 | C14: =C13*(1+$D$5) -> 97364.941 | D14: =(E13+C14/2)*(1-$D$7)*$D$6 -> 19338.503 | E14: =E13+C14+D14 -> 524656.23 | F14: =PV($D$5,B14,0,-E14) -> 487017.56 | G14: =G13+1 -> 5 | H14: =H13*(1+$I$5) -> 99209.897 | I14: =(I13-H14/2)*$I$6*(1-$I$7)+I13-H14 -> 1390269.9 | J14: samt alle de gule felter (husk ingen formler) | P14: tillæg enlig | Q14: 8329 | R14: =Q14*12 -> 99948
B15: =B14+1 -> 6 | C15: =C14*(1+$D$5) -> 98825.415 | D15: =(E14+C15/2)*(1-$D$7)*$D$6 -> 24311.819 | E15: =E14+C15+D15 -> 647793.46 | F15: =PV($D$5,B15,0,-E15) -> 592434.46 | G15: =G14+1 -> 6 | H15: =H14*(1+$I$5) -> 100698.04 | I15: =(I14-H15/2)*$I$6*(1-$I$7)+I14-H15 -> 1323619.2 | P15: tillæg par | Q15: 4262 | R15: =Q15*12 -> 51144 | S15: pr. stk
B16: =B15+1 -> 7 | C16: =C15*(1+$D$5) -> 100307.8 | D16: =(E15+C16/2)*(1-$D$7)*$D$6 -> 29558.071 | E16: =E15+C16+D16 -> 777659.33 | F16: =PV($D$5,B16,0,-E16) -> 700691.89 | G16: =G15+1 -> 7 | H16: =H15*(1+$I$5) -> 102208.52 | I16: =(I15-H16/2)*$I$6*(1-$I$7)+I15-H16 -> 1253745.3
B17: =B16+1 -> 8 | C17: =C16*(1+$D$5) -> 101812.41 | D17: =(E16+C17/2)*(1-$D$7)*$D$6 -> 35089.751 | E17: =E16+C17+D17 -> 914561.5 | F17: =PV($D$5,B17,0,-E17) -> 811866.41 | G17: =G16+1 -> 8 | H17: =H16*(1+$I$5) -> 103741.64 | I17: =(I16-H17/2)*$I$6*(1-$I$7)+I16-H17 -> 1180543.3 | P17: ATP | Q17: pr. mdr | R17: pr. år
B18: =B17+1 -> 9 | C18: =C17*(1+$D$5) -> 103339.6 | D18: =(E17+C18/2)*(1-$D$7)*$D$6 -> 40919.895 | E18: =E17+C18+D18 -> 1058821 | F18: =PV($D$5,B18,0,-E18) -> 926036.62 | G18: =G17+1 -> 9 | H18: =H17*(1+$I$5) -> 105297.77 | I18: =(I17-H18/2)*$I$6*(1-$I$7)+I17-H18 -> 1103905.3 | P18: Max udbetaling | Q18: =R18/12 -> 2343.25 | R18: 28119
B19: =B18+1 -> 10 | C19: =C18*(1+$D$5) -> 104889.69 | D19: =(E18+C19/2)*(1-$D$7)*$D$6 -> 47062.108 | E19: =E18+C19+D19 -> 1210772.8 | F19: =PV($D$5,B19,0,-E19) -> 1043283.2 | G19: =G18+1 -> 10 | H19: =H18*(1+$I$5) -> 106877.23 | I19: =(I18-H19/2)*$I$6*(1-$I$7)+I18-H19 -> 1023720.5
B20: =B19+1 -> 11 | C20: =C19*(1+$D$5) -> 106463.04 | D20: =(E19+C20/2)*(1-$D$7)*$D$6 -> 53530.583 | E20: =E19+C20+D20 -> 1370766.4 | F20: =PV($D$5,B20,0,-E20) -> 1163689.2 | G20: =G19+1 -> 11 | H20: =H19*(1+$I$5) -> 108480.39 | I20: =(I19-H20/2)*$I$6*(1-$I$7)+I19-H20 -> 939874.57 | P20: Årsløn før skat | R20: =80000*12 -> 960000
B21: =B20+1 -> 12 | C21: =C20*(1+$D$5) -> 108059.98 | D21: =(E20+C21/2)*(1-$D$7)*$D$6 -> 60340.128 | E21: =E20+C21+D21 -> 1539166.5 | F21: =PV($D$5,B21,0,-E21) -> 1287339.5 | G21: =G20+1 -> 12 | H21: =H20*(1+$I$5) -> 110107.6 | I21: =(I20-H21/2)*$I$6*(1-$I$7)+I20-H21 -> 852250.27 | P21: 75%/80% af løn | Q21: 0.8 | R21: =R20*Q21 -> 768000
B22: =B21+1 -> 13 | C22: =C21*(1+$D$5) -> 109680.88 | D22: =(E21+C22/2)*(1-$D$7)*$D$6 -> 67506.195 | E22: =E21+C22+D22 -> 1716353.6 | F22: =PV($D$5,B22,0,-E22) -> 1414321.7 | G22: =G21+1 -> 13 | H22: =H21*(1+$I$5) -> 111759.21 | I22: =(I21-H22/2)*$I$6*(1-$I$7)+I21-H22 -> 760726.84 | P22: Folkepension | R22: =R13 -> 86376 | S22: juster så det passer
B23: =B22+1 -> 14 | C23: =C22*(1+$D$5) -> 111326.1 | D23: =(E22+C23/2)*(1-$D$7)*$D$6 -> 75044.905 | E23: =E22+C23+D23 -> 1902724.6 | F23: =PV($D$5,B23,0,-E23) -> 1544725.6 | G23: =G22+1 -> 14 | H23: =H22*(1+$I$5) -> 113435.6 | I23: =(I22-H23/2)*$I$6*(1-$I$7)+I22-H23 -> 665180.11 | P23: Atp | R23: 17900 | S23: =S22 -> juster så det passer
B24: =B23+1 -> 15 | C24: =C23*(1+$D$5) -> 112995.99 | D24: =(E23+C24/2)*(1-$D$7)*$D$6 -> 82973.077 | E24: =E23+C24+D24 -> 2098693.7 | F24: =PV($D$5,B24,0,-E24) -> 1678643.3 | G24: =G23+1 -> 15 | H24: =H23*(1+$I$5) -> 115137.14 | I24: =(I23-H24/2)*$I$6*(1-$I$7)+I23-H24 -> 565482.38 | P24: Forventet udb. Pension | R24: =26500/2+27000/2+383000/2+92000+H10 -> 403724 | S24: evt. pensionsinfo
B25: =B24+1 -> 16 | C25: =C24*(1+$D$5) -> 114690.93 | D25: =(E24+C25/2)*(1-$D$7)*$D$6 -> 91308.258 | E25: =E24+C25+D25 -> 2304692.9 | F25: =PV($D$5,B25,0,-E25) -> 1816169.5 | G25: =G24+1 -> 16 | H25: =H24*(1+$I$5) -> 116864.19 | I25: =(I24-H25/2)*$I$6*(1-$I$7)+I24-H25 -> 461502.34 | P25: Friværdi + anden formue | R25: =K9 -> 260000 | S25: ***
B26: =B25+1 -> 17 | C26: =C25*(1+$D$5) -> 116411.29 | D26: =(E25+C26/2)*(1-$D$7)*$D$6 -> 100068.75 | E26: =E25+C26+D26 -> 2521172.9 | F26: =PV($D$5,B26,0,-E26) -> 1957401.5 | G26: =G25+1 -> 17 | H26: =H25*(1+$I$5) -> 118617.16 | I26: =(I25-H26/2)*$I$6*(1-$I$7)+I25-H26 -> 353104.92 | P26: Mangler hvert år | R26: =R21-R22-R23-R24-R25 -> 0
B27: =B26+1 -> 18 | C27: =C26*(1+$D$5) -> 118157.46 | D27: =(E26+C27/2)*(1-$D$7)*$D$6 -> 109273.66 | E27: =E26+C27+D27 -> 2748604 | F27: =PV($D$5,B27,0,-E27) -> 2102439.1 | G27: =G26+1 -> 18 | H27: =H26*(1+$I$5) -> 120396.41 | I27: =(I26-H27/2)*$I$6*(1-$I$7)+I26-H27 -> 240151.27
B28: =B27+1 -> 19 | C28: =C27*(1+$D$5) -> 119929.82 | D28: =(E27+C28/2)*(1-$D$7)*$D$6 -> 118942.89 | E28: =E27+C28+D28 -> 2987476.7 | F28: =PV($D$5,B28,0,-E28) -> 2251384.8 | G28: =G27+1 -> 19 | H28: =H27*(1+$I$5) -> 122202.36 | I28: =(I27-H28/2)*$I$6*(1-$I$7)+I27-H28 -> 122498.57 | P28: Udbetalt pr. år | R28: =R22+R23+R24+R25 -> 768000
B29: =B28+1 -> 20 | C29: =C28*(1+$D$5) -> 121728.77 | D29: =(E28+C29/2)*(1-$D$7)*$D$6 -> 129097.25 | E29: =E28+C29+D29 -> 3238302.8 | F29: =PV($D$5,B29,0,-E29) -> 2404344 | G29: =G28+1 -> 20 | H29: =H28*(1+$I$5) -> 124035.39 | I29: =(I28-H29/2)*$I$6*(1-$I$7)+I28-H29 -> -1.4551915e-10 | P29: Udbetalt i % | R29: =R28/R20 -> 0.8
B30: =B29+1 -> 21 | C30: =C29*(1+$D$5) -> 123554.7 | D30: =(E29+C30/2)*(1-$D$7)*$D$6 -> 139758.39 | E30: =E29+C30+D30 -> 3501615.9 | F30: =PV($D$5,B30,0,-E30) -> 2561424.8 | G30: =G29+1 -> 21 | H30: =H29*(1+$I$5) -> 125895.92 | I30: =(I29-H30/2)*$I$6*(1-$I$7)+I29-H30 -> -127495.43
B31: =B30+1 -> 22 | C31: =C30*(1+$D$5) -> 125408.02 | D31: =(E30+C31/2)*(1-$D$7)*$D$6 -> 150948.95 | E31: =E30+C31+D31 -> 3777972.8 | F31: =PV($D$5,B31,0,-E31) -> 2722738.3 | G31: =G30+1 -> 22 | H31: =H30*(1+$I$5) -> 127784.36 | I31: =(I30-H31/2)*$I$6*(1-$I$7)+I30-H31 -> -260142.96 | P31: mangler at betale pr. mdr. | R31: =E2 -> 9555.8034 | S31: før skat
B32: =B31+1 -> 23 | C32: =C31*(1+$D$5) -> 127289.14 | D32: =(E31+C32/2)*(1-$D$7)*$D$6 -> 162692.5 | E32: =E31+C32+D32 -> 4067954.5 | F32: =PV($D$5,B32,0,-E32) -> 2888398.5 | G32: =G31+1 -> 23 | H32: =H31*(1+$I$5) -> 129701.13 | I32: =(I31-H32/2)*$I$6*(1-$I$7)+I31-H32 -> -398102.17 | P32: mangler at betale pr. mdr. | R32: =R31*0.48 -> 4586.7856 | S32: efter skat | T32: gæt topskat
B33: =B32+1 -> 24 | C33: =C32*(1+$D$5) -> 129198.48 | D33: =(E32+C33/2)*(1-$D$7)*$D$6 -> 175013.65 | E33: =E32+C33+D33 -> 4372166.6 | F33: =PV($D$5,B33,0,-E33) -> 3058522.6 | G33: =G32+1 -> 24 | H33: =H32*(1+$I$5) -> 131646.65 | I33: =(I32-H33/2)*$I$6*(1-$I$7)+I32-H33 -> -541537.16 | P33: mangler at betale pr. mdr. | R33: =#REF! -> #REF! | S33: efter skat | T33: Jf. skatteberegner. Hans indkomst er ikke stor nok til at han kan trække hele imerindskuddet fra i topskatten
B34: =B33+1 -> 25 | C34: =C33*(1+$D$5) -> 131136.46 | D34: =(E33+C34/2)*(1-$D$7)*$D$6 -> 187938.07 | E34: =E33+C34+D34 -> 4691241.1 | F34: =PV($D$5,B34,0,-E34) -> 3233230.7 | G34: =G33+1 -> 25 | H34: =H33*(1+$I$5) -> 133621.35 | I34: =(I33-H34/2)*$I$6*(1-$I$7)+I33-H34 -> -690616.63
B35: =B34+1 -> 26 | C35: =C34*(1+$D$5) -> 133103.51 | D35: =(E34+C35/2)*(1-$D$7)*$D$6 -> 201492.53 | E35: =E34+C35+D35 -> 5025837.2 | F35: =PV($D$5,B35,0,-E35) -> 3412646.6 | G35: =G34+1 -> 26 | H35: =H34*(1+$I$5) -> 135625.67 | I35: =(I34-H35/2)*$I$6*(1-$I$7)+I34-H35 -> -845513.99 | K35: Antag at pensionsalderes efter 2030 fortsat er 68 år
B36: =B35+1 -> 27 | C36: =C35*(1+$D$5) -> 135100.06 | D36: =(E35+C36/2)*(1-$D$7)*$D$6 -> 215704.95 | E36: =E35+C36+D36 -> 5376642.2 | F36: =PV($D$5,B36,0,-E36) -> 3596896.9 | G36: =G35+1 -> 27 | H36: =H35*(1+$I$5) -> 137660.05 | I36: =(I35-H36/2)*$I$6*(1-$I$7)+I35-H36 -> -1006407.5 | K36: Dette er en meget forenklet billede af folkepensionsalderen - vi har bestemt at det kun er disse I skal kende​
B37: =B36+1 -> 28 | C37: =C36*(1+$D$5) -> 137126.56 | D37: =(E36+C37/2)*(1-$D$7)*$D$6 -> 230604.45 | E37: =E36+C37+D37 -> 5744373.2 | F37: =PV($D$5,B37,0,-E37) -> 3786112.1 | G37: =G36+1 -> 28 | H37: =H36*(1+$I$5) -> 139724.95 | I37: =(I36-H37/2)*$I$6*(1-$I$7)+I36-H37 -> -1173480.5 | K37: Kilde: https://star.dk/ydelser/pension-og-efterloen/folkepension-og-foertidspension/folkepension/folkepensionsalderen-nu-og-fremover/​
B38: =B37+1 -> 29 | C38: =C37*(1+$D$5) -> 139183.46 | D38: =(E37+C38/2)*(1-$D$7)*$D$6 -> 246221.41 | E38: =E37+C38+D38 -> 6129778.1 | F38: =PV($D$5,B38,0,-E38) -> 3980425.7 | G38: =G37+1 -> 29 | H38: =H37*(1+$I$5) -> 141820.83 | I38: =(I37-H38/2)*$I$6*(1-$I$7)+I37-H38 -> -1346921.3
B39: =B38+1 -> 30 | C39: =C38*(1+$D$5) -> 141271.21 | D39: =(E38+C39/2)*(1-$D$7)*$D$6 -> 262587.52 | E39: =E38+C39+D39 -> 6533636.8 | F39: =PV($D$5,B39,0,-E39) -> 4179975.3 | G39: =G38+1 -> 30 | H39: =H38*(1+$I$5) -> 143948.14 | I39: =(I38-H39/2)*$I$6*(1-$I$7)+I38-H39 -> -1526923.6
B40: =B39+1 -> 31 | C40: =C39*(1+$D$5) -> 143390.28 | D40: =(E39+C40/2)*(1-$D$7)*$D$6 -> 279735.81 | E40: =E39+C40+D40 -> 6956762.9 | F40: =PV($D$5,B40,0,-E40) -> 4384902 | G40: =G39+1 -> 31 | H40: =H39*(1+$I$5) -> 146107.36 | I40: =(I39-H40/2)*$I$6*(1-$I$7)+I39-H40 -> -1713686.3
B41: =B40+1 -> 32 | C41: =C40*(1+$D$5) -> 145541.13 | D41: =(E40+C41/2)*(1-$D$7)*$D$6 -> 297700.74 | E41: =E40+C41+D41 -> 7400004.7 | F41: =PV($D$5,B41,0,-E41) -> 4595350.5 | G41: =G40+1 -> 32 | H41: =H40*(1+$I$5) -> 148298.97 | I41: =(I40-H41/2)*$I$6*(1-$I$7)+I40-H41 -> -1907414.2
...

Sheet Skat salg (80%)
B1: Skatteberegningsprogram - enlig | C1: År 2025
C2: Person | I2: =C2 -> Person
B3: Privat indskud på ratepension (og ophørende livrente) | C3: 63100 | I3: Beregnings-grundlag | J3: Beregnet skat
B4: Privat indskud på livrente | C4: =58100+'Tom salg mangler (80%)'!D2 -> 172769.64 | F4: Beregning af skat | G4: Procent | H4: Fradrag
B5: Alder | C5: 53 | F5: Bundskat | G5: =Bundskat -> 0.1201 | H5: =Personfradrag -> 51600 | I5: =IF(C35>=0,C31+C35-H5,C31-H5) -> 595730.36 | J5: =+IF(I5>0,G5*I5,0) -> 71547.216
B6: Har fri telefon (ja/nej) | C6: nej | F6: Topskat | G6: =Topskat -> 0.15 | H6: =TopSkatGranse -> 611800 | I6: =MAX((C70-$H$6),0) -> 35530.36 | J6: =G6*I6 -> 5329.554
B7: Fagforening | C7: 0 | F7: Sundhedsbidrag | G7: =Sundhedsbidrag -> 0 | H7: =Personfradrag -> 51600 | I7: =($C$45+AB29)-(H7+AB43) -> 510414.36 | J7: =+IF(I7>0,I7*G7,0) -> 0
B8: A-kasse og efterløn | C8: 0 | F8: Kommuneskat | G8: =C13 -> 0.2438 | H8: =Personfradrag -> 51600 | I8: =($C$45+AB29)-(H8+AB44) -> 510414.36 | J8: =+IF(I8>0,$C$13*I8,0) -> 124439.02
B9: Antal km til arbejde (tur/retur) | C9: 0 | F9: Kirkeskat | G9: =C14 -> 0.006 | H9: =Personfradrag -> 51600 | I9: =($C$45+AB29)-(H9+AB45) -> 510414.36 | J9: =+IF(I9>0,$C$14*I9,0) -> 3062.4862
B10: Antal arbejdsdage | C10: 0 | J10: =SUM(J5:J9) -> 204378.28
B11: Medlem af Folkekirken (ja/nej) | C11: ja
B12: Vælg Kommune | C12: Lyngby-Taarbæk | F12: Evt skattetillæg af neg. KI under 50.000 | J12: =IF(C35>=0,0,IF(C35>=GranseNegKIEnlig,TillagNegKI*C35,TillagNegKI*GranseNegKIEnlig)) -> 0
B13: Kommuneskattesats | C13: =VLOOKUP($C$12,Skattesatser!$B$6:$E$103,2)/100 -> 0.2438 | F13: Evt. nedslag i topskatten (lønindkomst) | I13: =IF($C$73>SkraatSkatteloftPI,$C$73-SkraatSkatteloftPI,0) -> 0 | J13: =-I13*C75 -> 0
B14: Kirkeskattesats | C14: =IF(C11="ja",VLOOKUP($C$12,Skattesatser!$B$6:$E$103,3)/100,0) -> 0.006 | F14: Evt. nedslag i topskatten (kapitalindkomst) | I14: =IF($C$73>SkraatSkatteloftKI,$C$73-SkraatSkatteloftKI,0) -> 0.0939 | J14: =-I14*C76 -> 0
B15: Grundskyldssats | C15: =VLOOKUP($C$12,Skattesatser!$B$6:$E$103,4)/1000 -> 0.0067 | J15: =SUM(J10:J14) -> 204378.28
B16: Ejendomsværdi (offentlig) | C16: 0
B17: Grundværdi (offentlig) | C17: 0
B18: Evt skatterabat (bolig købt før 1.jan.2024) | C18: 0 | F18: Indkomstskat i alt (incl. AM-bidrag) | J18: =J15+C27 -> 281178.28
F19: Ejendomsværdiskat | J19: =+F63 -> 0
B20: Lønindkomst (efter evt. ATP) | C20: =12*80000 -> 960000 | F20: Grundskyld | J20: =F64 -> 0
B21: arbejdsgiverpensionsordning % (kun eget indskud) | C21: 0 | F21: Skatterabat | J21: =-C18 -> 0
B22: - arbejdsgiverpensionsordning DKK (kun eget indskud) | C22: =C21*C20 -> 0
B23: + anden AM-pligtig indkomst | C23: 0 | F23: Skat i alt | J23: =SUM(J18:J21) -> 281178.28
B24: + fri telefon | C24: =IF(C6="ja",FriTelefon,0) -> 0
B25: = Beregningsgrundlag for AM-bidrag | C25: =C20-C22+C23+C24 -> 960000
F26: Udbetalt efter skat | I26: =C2 -> Person
B27: - AM-bidrag | C27: =ArbBidrag*C25 -> 76800 | I27: Pr. år | J27: Pr. måned
B28: + Ikke AM-pligtig indkomst (SU, dagpenge, pension etc.) | C28: 0 | F28: Lønindkomst | I28: =C20+C23+C28 -> 960000 | J28: =I28/12 -> 80000
B29: - Eget indskud på ratepension (husk også at indtaste i budget) | C29: =IF(C3>RatepensionMax,RatepensionMax,C3) -> 63100 | F29: - arbejdsgiver pensionsordning | I29: =C22 -> 0 | J29: =I29/12 -> 0
B30: - Eget indskud på livrente (husk også at indtaste i budget) | C30: =+C4 -> 172769.64 | F30: - skat | I30: =J23 -> 281178.28 | J30: =I30/12 -> 23431.523
B31: = Personlig indkomst (PI) | C31: =C25-C27+C28-C29-C30 -> 647330.36 | F31: Udbetalt efter skat | I31: =I28-I29-I30 -> 678821.72 | J31: =I31/12 -> 56568.477
B33: + Renteindtægter | C33: 0
B34: - Renteudgfter | C34: 0
B35: + Kapitalindkomst (KI) i alt | C35: =+C33-C34 -> 0 | F35: Samlet skat i dag | I35: ='Skat før'!J23 -> 352854.72
F36: Samlet skat efter egen indbetaling | I36: =J23 -> 281178.28
B37: Beskæftigelsesfradrag | C37: =MIN(+($C$25+$C$22*3)*BFradragProc,BFradragMax) -> 55600 | F37: Sparet skat | I37: =I35-I36 -> 71676.447
B38: Jobfradrag | C38: =MAX(0,MIN(+($C$25+$C$22*3-Jfradraggranse)*Jfradragproc,JfradragMax)) -> 2900 | F38: Pensionsindbetaling | I38: ='Tom salg mangler (80%)'!D2 -> 114669.64
B39: Ekstra pensionsfradrag | C39: =IF(C5<=52,MIN(+(C3+C4+C22*3)*EPENfradragProc,EPENfradragMax),MIN(+(C3+C4+C22*3)*EPENSeniorProc,EPENSeniorMax)) -> 26816 | F39: Netto betalt | I39: =I38-I37 -> 42993.194 | J39: =I39/12 -> 3582.7661
B40: Fagforening, A-kasse og efterløn | C40: =IF(C7>FagforeningMax,FagforeningMax,C7)+C8 -> 0
B41: Befordring | C41: =+$H$56 -> 0
...

Sheet Skattesatser
